2023-12-27 19:15:54,291 INFO: Microblog startup [in E:\pythonProject\microblog\app\__init__.py:56]
2023-12-27 19:16:08,549 ERROR: Exception on /edit_profile [POST] [in E:\pythonProject\microblog\venv\lib\site-packages\flask\app.py:825]
Traceback (most recent call last):
  File "E:\pythonProject\microblog\venv\lib\site-packages\sqlalchemy\engine\base.py", line 1969, in _exec_single_context
    self.dialect.do_execute(
  File "E:\pythonProject\microblog\venv\lib\site-packages\sqlalchemy\engine\default.py", line 922, in do_execute
    cursor.execute(statement, parameters)
sqlite3.IntegrityError: UNIQUE constraint failed: user.username

The above exception was the direct cause of the following exception:

Traceback (most recent call last):
  File "E:\pythonProject\microblog\venv\lib\site-packages\flask\app.py", line 1455, in wsgi_app
    response = self.full_dispatch_request()
  File "E:\pythonProject\microblog\venv\lib\site-packages\flask\app.py", line 869, in full_dispatch_request
    rv = self.handle_user_exception(e)
  File "E:\pythonProject\microblog\venv\lib\site-packages\flask\app.py", line 867, in full_dispatch_request
    rv = self.dispatch_request()
  File "E:\pythonProject\microblog\venv\lib\site-packages\flask\app.py", line 852, in dispatch_request
    return self.ensure_sync(self.view_functions[rule.endpoint])(**view_args)
  File "E:\pythonProject\microblog\venv\lib\site-packages\flask_login\utils.py", line 290, in decorated_view
    return current_app.ensure_sync(func)(*args, **kwargs)
  File "E:\pythonProject\microblog\app\routes.py", line 100, in edit_profile
    db.session.commit()
  File "E:\pythonProject\microblog\venv\lib\site-packages\sqlalchemy\orm\scoping.py", line 598, in commit
    return self._proxied.commit()
  File "E:\pythonProject\microblog\venv\lib\site-packages\sqlalchemy\orm\session.py", line 1969, in commit
    trans.commit(_to_root=True)
  File "<string>", line 2, in commit
  File "E:\pythonProject\microblog\venv\lib\site-packages\sqlalchemy\orm\state_changes.py", line 139, in _go
    ret_value = fn(self, *arg, **kw)
  File "E:\pythonProject\microblog\venv\lib\site-packages\sqlalchemy\orm\session.py", line 1256, in commit
    self._prepare_impl()
  File "<string>", line 2, in _prepare_impl
  File "E:\pythonProject\microblog\venv\lib\site-packages\sqlalchemy\orm\state_changes.py", line 139, in _go
    ret_value = fn(self, *arg, **kw)
  File "E:\pythonProject\microblog\venv\lib\site-packages\sqlalchemy\orm\session.py", line 1231, in _prepare_impl
    self.session.flush()
  File "E:\pythonProject\microblog\venv\lib\site-packages\sqlalchemy\orm\session.py", line 4312, in flush
    self._flush(objects)
  File "E:\pythonProject\microblog\venv\lib\site-packages\sqlalchemy\orm\session.py", line 4448, in _flush
    transaction.rollback(_capture_exception=True)
  File "E:\pythonProject\microblog\venv\lib\site-packages\sqlalchemy\util\langhelpers.py", line 146, in __exit__
    raise exc_value.with_traceback(exc_tb)
  File "E:\pythonProject\microblog\venv\lib\site-packages\sqlalchemy\orm\session.py", line 4408, in _flush
    flush_context.execute()
  File "E:\pythonProject\microblog\venv\lib\site-packages\sqlalchemy\orm\unitofwork.py", line 466, in execute
    rec.execute(self)
  File "E:\pythonProject\microblog\venv\lib\site-packages\sqlalchemy\orm\unitofwork.py", line 642, in execute
    util.preloaded.orm_persistence.save_obj(
  File "E:\pythonProject\microblog\venv\lib\site-packages\sqlalchemy\orm\persistence.py", line 85, in save_obj
    _emit_update_statements(
  File "E:\pythonProject\microblog\venv\lib\site-packages\sqlalchemy\orm\persistence.py", line 909, in _emit_update_statements
    c = connection.execute(
  File "E:\pythonProject\microblog\venv\lib\site-packages\sqlalchemy\engine\base.py", line 1416, in execute
    return meth(
  File "E:\pythonProject\microblog\venv\lib\site-packages\sqlalchemy\sql\elements.py", line 516, in _execute_on_connection
    return connection._execute_clauseelement(
  File "E:\pythonProject\microblog\venv\lib\site-packages\sqlalchemy\engine\base.py", line 1639, in _execute_clauseelement
    ret = self._execute_context(
  File "E:\pythonProject\microblog\venv\lib\site-packages\sqlalchemy\engine\base.py", line 1848, in _execute_context
    return self._exec_single_context(
  File "E:\pythonProject\microblog\venv\lib\site-packages\sqlalchemy\engine\base.py", line 1988, in _exec_single_context
    self._handle_dbapi_exception(
  File "E:\pythonProject\microblog\venv\lib\site-packages\sqlalchemy\engine\base.py", line 2343, in _handle_dbapi_exception
    raise sqlalchemy_exception.with_traceback(exc_info[2]) from e
  File "E:\pythonProject\microblog\venv\lib\site-packages\sqlalchemy\engine\base.py", line 1969, in _exec_single_context
    self.dialect.do_execute(
  File "E:\pythonProject\microblog\venv\lib\site-packages\sqlalchemy\engine\default.py", line 922, in do_execute
    cursor.execute(statement, parameters)
sqlalchemy.exc.IntegrityError: (sqlite3.IntegrityError) UNIQUE constraint failed: user.username
[SQL: UPDATE user SET username=?, about_me=? WHERE user.id = ?]
[parameters: ('1', '你可真是个大聪明呀', 1)]
(Background on this error at: https://sqlalche.me/e/20/gkpj)
2023-12-29 15:37:01,635 INFO: Microblog startup [in E:\pythonProject\microblog\app\__init__.py:56]
2023-12-29 15:39:08,308 INFO: Microblog startup [in E:\pythonProject\microblog\app\__init__.py:56]
2023-12-29 15:50:53,162 INFO: Microblog startup [in E:\pythonProject\microblog\app\__init__.py:56]
2023-12-29 16:44:10,881 INFO: Microblog startup [in E:\pythonProject\microblog\app\__init__.py:56]
2023-12-29 16:49:18,170 INFO: Microblog startup [in E:\pythonProject\microblog\app\__init__.py:56]
